Workbook

Sheet DashBoard
A1: model / code | B1: Rate of successful conversion of C code to a mermaid diagram (n=100) | C1: Response tokens ave. | D1: backticks appear in resopnse
A2: =SUBSTITUTE(sheetNameRef!$A1, "-", " / ",2) -> GPT-3.5 / ft_strlen | B2: =COUNTIF(INDIRECT("'"&sheetNameRef!$A1&"'!A2:A101"),1) -> 90 | C2: =AVERAGEIF(INDIRECT("'"&sheetNameRef!$A1&"'!$A$2:$A$101"),1,INDIRECT("'"&sheetNameRef!$A1&"'!$B$2:$B$101")) -> 131.14444 | D2: =COUNTIF(INDIRECT("'"&sheetNameRef!$A1&"'!E2:E101"),"```*") -> 1
A3: =SUBSTITUTE(sheetNameRef!$A2, "-", " / ",2) -> GPT-3.5 / ft_bzero | B3: =COUNTIF(INDIRECT("'"&sheetNameRef!$A2&"'!A2:A101"),1) -> 56 | C3: =AVERAGEIF(INDIRECT("'"&sheetNameRef!$A2&"'!$A$2:$A$101"),1,INDIRECT("'"&sheetNameRef!$A2&"'!$B$2:$B$101")) -> 313.67857 | D3: =COUNTIF(INDIRECT("'"&sheetNameRef!$A2&"'!E2:E101"),"```*") -> 0
A4: =SUBSTITUTE(sheetNameRef!$A3, "-", " / ",2) -> GPT-3.5 / ft_memmove | B4: =COUNTIF(INDIRECT("'"&sheetNameRef!$A3&"'!A2:A101"),1) -> 61 | C4: =AVERAGEIF(INDIRECT("'"&sheetNameRef!$A3&"'!$A$2:$A$101"),1,INDIRECT("'"&sheetNameRef!$A3&"'!$B$2:$B$101")) -> 203.16393 | D4: =COUNTIF(INDIRECT("'"&sheetNameRef!$A3&"'!E2:E101"),"```*") -> 0
A5: =SUBSTITUTE(sheetNameRef!$A4, "-", " / ",2) -> GPT-3.5 / ft_atoi | B5: =COUNTIF(INDIRECT("'"&sheetNameRef!$A4&"'!A2:A101"),1) -> 40 | C5: =AVERAGEIF(INDIRECT("'"&sheetNameRef!$A4&"'!$A$2:$A$101"),1,INDIRECT("'"&sheetNameRef!$A4&"'!$B$2:$B$101")) -> 275.875 | D5: =COUNTIF(INDIRECT("'"&sheetNameRef!$A4&"'!E2:E101"),"```*") -> 1
A6: =SUBSTITUTE(sheetNameRef!$A5, "-", " / ",2) -> GPT-3.5 / ft_split | B6: =COUNTIF(INDIRECT("'"&sheetNameRef!$A5&"'!A2:A101"),1) -> 40 | C6: =AVERAGEIF(INDIRECT("'"&sheetNameRef!$A5&"'!$A$2:$A$101"),1,INDIRECT("'"&sheetNameRef!$A5&"'!$B$2:$B$101")) -> 406.05 | D6: =COUNTIF(INDIRECT("'"&sheetNameRef!$A5&"'!E2:E101"),"```*") -> 1
A7: =SUBSTITUTE(sheetNameRef!$A6, "-", " / ",2) -> GPT-4 / ft_strlen | B7: =COUNTIF(INDIRECT("'"&sheetNameRef!$A6&"'!A2:A101"),1) -> 100 | C7: =AVERAGEIF(INDIRECT("'"&sheetNameRef!$A6&"'!$A$2:$A$101"),1,INDIRECT("'"&sheetNameRef!$A6&"'!$B$2:$B$101")) -> 123.67
A8: =SUBSTITUTE(sheetNameRef!$A7, "-", " / ",2) -> GPT-4 / ft_bzero | B8: =COUNTIF(INDIRECT("'"&sheetNameRef!$A7&"'!A2:A101"),1) -> 98 | C8: =AVERAGEIF(INDIRECT("'"&sheetNameRef!$A7&"'!$A$2:$A$101"),1,INDIRECT("'"&sheetNameRef!$A7&"'!$B$2:$B$101")) -> 202.23469
A9: =SUBSTITUTE(sheetNameRef!$A8, "-", " / ",2) -> GPT-4 / ft_memmove | B9: =COUNTIF(INDIRECT("'"&sheetNameRef!$A8&"'!A2:A101"),1) -> 86 | C9: =AVERAGEIF(INDIRECT("'"&sheetNameRef!$A8&"'!$A$2:$A$101"),1,INDIRECT("'"&sheetNameRef!$A8&"'!$B$2:$B$101")) -> 269.47674
A10: =SUBSTITUTE(sheetNameRef!$A9, "-", " / ",2) -> GPT-4 / ft_atoi | B10: =COUNTIF(INDIRECT("'"&sheetNameRef!$A9&"'!A2:A101"),1) -> 68 | C10: =AVERAGEIF(INDIRECT("'"&sheetNameRef!$A9&"'!$A$2:$A$101"),1,INDIRECT("'"&sheetNameRef!$A9&"'!$B$2:$B$101")) -> 354.97059
A11: =SUBSTITUTE(sheetNameRef!$A10, "-", " / ",2) -> GPT-4 / ft_split | B11: =COUNTIF(INDIRECT("'"&sheetNameRef!$A10&"'!A2:A101"),1) -> 67 | C11: =AVERAGEIF(INDIRECT("'"&sheetNameRef!$A10&"'!$A$2:$A$101"),1,INDIRECT("'"&sheetNameRef!$A10&"'!$B$2:$B$101")) -> 655.37313
F12: name | G12: url
F13: =sheetNameRef!$A1 -> GPT-3.5-ft_strlen | G13: {=(INDEX(INDIRECT("'" & $F13 & "'!$F$2:$F$101"), MATCH(MAX(IF(INDIRECT("'" & $F13 & "'!$A$2:$A$101")=1, INDIRECT("'" & $F13 & "'!$B$2:$B$101"), 0)), INDIRECT("'" & $F13 & "'!$B$2:$B$101"), 0)))} -> https://mermaid.ink/img/JSV7aW5pdDp7J3RoZW1lJzonZm9yZXN0J319JSUKc2VxdWVuY2VEaWFncmFtCnBhcnRpY2lwYW50IE0gYXMgbWFpbigpCnBhcnRpY2lwYW50IEZTIGFzIGZ0X3N0cmxlbigpCnBhcnRpY2lwYW50IFBGIGFzIHByaW50ZigpCk0tPj5GUzogY2FsbCBmdF9zdHJsZW4oc3RyKQpub3RlIG92ZXIgRlM6IGkgPSAwCmxvb3Agd2hpbGUgc3RyW2ldICE9ICdcMCcKICAgIEZTLT4+RlM6IGluY3JlbWVudCBpCmVuZApGUy0tPj5NOiByZXR1cm4gaQpNLT4+UEY6IGNhbGwgcHJpbnRmKCJbJXNdIGlzICVkLlxuIiwgc3RyLCBpKQpQRi0tPj5NOiBQcmludCB0aGUgcmVzdWx0
F14: =sheetNameRef!$A2 -> GPT-3.5-ft_bzero | G14: {=INDEX(INDIRECT("'" & $F14 & "'!$F$2:$F$101"), MATCH(MAX(IF(INDIRECT("'" & $F14 & "'!$A$2:$A$101")=1, INDIRECT("'" & $F14 & "'!$B$2:$B$101"), 0)), INDIRECT("'" & $F14 & "'!$B$2:$B$101"), 0))} -> https://mermaid.ink/img/JSV7aW5pdDp7J3RoZW1lJzonZm9yZXN0J319JSUKc2VxdWVuY2VEaWFncmFtCnBhcnRpY2lwYW50IE0gYXMgbWFpbigpCnBhcnRpY2lwYW50IEZNQiBhcyBmdF9tZW1zZXQoKQpwYXJ0aWNpcGFudCBGQlogYXMgZnRfYnplcm8oKQpwYXJ0aWNpcGFudCBQIGFzIHByaW50ZigpCk0tPj5GQlo6IENhbGwgZnRfYnplcm8oc3RyLCA1KQpGQlotPj5GTUI6IENhbGwgZnRfbWVtc2V0KHN0ciwgMCwgNSkKbG9vcCB3aGlsZSBsZW4gPiAwCiAgICBub3RlIG92ZXIgRk1COiAqcHRyID0gdmFsCiAgICBGTUItPj5GTUI6IHB0cisrLCBsZW4tLQplbmQKTS0+PlA6IENhbGwgcHJpbnRmKCIwXG4iKQpNLT4+UDogQ2FsbCBwcmludGYoIiVjXG4iLCBzdHJbaV0pCk0tPj5GQlo6IENhbGwgZnRfYnplcm8oc3RyLCA1KQ==
F15: =sheetNameRef!$A3 -> GPT-3.5-ft_memmove | G15: {=INDEX(INDIRECT("'" & $F15 & "'!$F$2:$F$101"), MATCH(MAX(IF(INDIRECT("'" & $F15 & "'!$A$2:$A$101")=1, INDIRECT("'" & $F15 & "'!$B$2:$B$101"), 0)), INDIRECT("'" & $F15 & "'!$B$2:$B$101"), 0))} -> https://mermaid.ink/img/JSV7aW5pdDp7J3RoZW1lJzonZm9yZXN0J319JSUKc2VxdWVuY2VEaWFncmFtCnBhcnRpY2lwYW50IE0gYXMgbWFpbigpCnBhcnRpY2lwYW50IEZNIGFzIGZ0X21lbWNweSgpCnBhcnRpY2lwYW50IEZNViBhcyBmdF9tZW1tb3ZlKCkKcGFydGljaXBhbnQgUEYgYXMgcHJpbnRmKCkKTS0+PkZNVjogQ2FsbCBmdF9tZW1tb3ZlKGRlc3QsIHNyYywgMTEpCmFsdCBpZiBkIDwgcwpGTVYtPj5GTTogQ2FsbCBmdF9tZW1jcHkoZCwgcywgbGVuKQpGTS0+PkZNVjogQ2FsbCBmdF9tZW1jcHkoZCwgcywgbGVuKQpGTS0tPj5GTVY6IFJldHVybiBkc3QKZWxzZQpGTVYtPj5GTVY6IENvcHkgbGVuIGJ5dGVzIGZyb20gc3JjIHRvIGRzdAplbmQKTS0+PlBGOiBDYWxsIHByaW50ZigiY29waWVkIHN0cmluZyA6ICVzXG4iLCBkZXN0KQpQRi0tPj5NOiBQcmludCB0aGUgcmVzdWx0
F16: =sheetNameRef!$A4 -> GPT-3.5-ft_atoi | G16: {=INDEX(INDIRECT("'" & $F16 & "'!$F$2:$F$101"), MATCH(MAX(IF(INDIRECT("'" & $F16 & "'!$A$2:$A$101")=1, INDIRECT("'" & $F16 & "'!$B$2:$B$101"), 0)), INDIRECT("'" & $F16 & "'!$B$2:$B$101"), 0))} -> https://mermaid.ink/img/JSV7aW5pdDp7J3RoZW1lJzonZm9yZXN0J319JSUKc2VxdWVuY2VEaWFncmFtCnBhcnRpY2lwYW50IE0gYXMgbWFpbigpCnBhcnRpY2lwYW50IEZBIGFzIGZ0X2F0b2koKQpwYXJ0aWNpcGFudCBGSUQgYXMgZnRfaXNkaWdpdCgpCnBhcnRpY2lwYW50IEZJUyBhcyBmdF9pc3NwYWNlKCkKTS0+PkZBOiBDYWxsIGZ0X2F0b2koIjEyMzQ1Njc4OTAiKQpGQS0+PkZJUzogQ2FsbCBmdF9pc3NwYWNlKCcxJykKbG9vcCBXaGlsZSBpc3NwYWNlCiAgICBhbHQgaWYgKnN0ciA9PSAnLScgb3IgKnN0ciA9PSAnKycKICAgICAgICBGQS0tPj5GSVM6IFNraXAKICAgIGVsc2UKICAgICAgICBGSVMtPj5GSVM6IE1vdmUgdG8gbmV4dCBjaGFyYWN0ZXIKICAgIGVuZAplbmQKYWx0IGlmICpzdHIgPT0gJy0nCiAgICBub3RlIG92ZXIgRkE6IFNldCBpc19uZWcgPSAxCiAgICBGQS0+PkZBOiBNb3ZlIHRvIHRoZSBuZXh0IGNoYXJhY3RlcgplbHNlIGlmICpzdHIgPT0gJysnCiAgICBub3RlIG92ZXIgRkE6IFNldCBpc19uZWcgPSAwCiAgICBGQS0+PkZBOiBNb3ZlIHRvIHRoZSBuZXh0IGNoYXJhY3RlcgplbmQKbG9vcCBXaGlsZSBpc2RpZ2l0CiAgICBhbHQgaWYgaXNvdmVyZmxvdwogICAgICAgIG5vdGUgb3ZlciBGQTogQnJlYWsgdGhlIGxvb3AKICAgIGVsc2UKICAgICAgICBGQS0+PkZBOiBDYWxjdWxhdGUgbnVtCiAgICBlbmQKZW5kCmFsdCBpZiBpc19uZWcKICAgIEZBLS0+Pk06IHJldHVybiAoLW51bSkKZWxzZQogICAgRkEtLT4+TTogcmV0dXJuIG51bQplbmQKTS0+PnByaW50ZjogY2FsbCBwcmludGYoIiVkXG4iLCBpKQpwcmludGYtLT4+TTogUHJpbnQgdGhlIHJlc3VsdA==
F17: =sheetNameRef!$A5 -> GPT-3.5-ft_split | G17: {=INDEX(INDIRECT("'" & $F17 & "'!$F$2:$F$101"), MATCH(MAX(IF(INDIRECT("'" & $F17 & "'!$A$2:$A$101")=1, INDIRECT("'" & $F17 & "'!$B$2:$B$101"), 0)), INDIRECT("'" & $F17 & "'!$B$2:$B$101"), 0))} -> https://mermaid.ink/img/JSV7aW5pdDp7J3RoZW1lJzonZm9yZXN0J319JSUKc2VxdWVuY2VEaWFncmFtCnBhcnRpY2lwYW50IE0gYXMgbWFpbigpCnBhcnRpY2lwYW50IEZTTCBhcyBmdF9zdHJsZW4oKQpwYXJ0aWNpcGFudCBGTSBhcyBmdF9tZW1jcHkoKQpwYXJ0aWNpcGFudCBGUyBhcyBmdF9zdWJzdHIoKQpwYXJ0aWNpcGFudCBGTVMgYXMgZnRfbW92ZV9zcGxpdHN0YXJ0KCkKcGFydGljaXBhbnQgRkdTIGFzIGZ0X2dldF9zcGxpdGxlbigpCnBhcnRpY2lwYW50IEZHVCBhcyBmdF9nZXRfc3BsaXR0aW1lcygpCnBhcnRpY2lwYW50IEZGQSBhcyBmdF9mcmVlX2FycmF5KCkKTS0+PkZTOiBjYWxsIGZ0X3NwbGl0KHN0ciwgYykKYWx0IGlmIHN0ciBpcyBOVUxMCiAgICBGUy0tPj5NOiBSZXR1cm4gTlVMTAplbHNlIG90aGVyd2lzZQogICAgRkdULT4+RlM6IGNhbGwgZnRfZ2V0X3NwbGl0dGltZXMKICAgIGxvb3AgZm9yIGVhY2ggc3BsaXQgcGFydAogICAgICAgIEZTLT4+Rk1TOiBjYWxsIGZ0X21vdmVfc3BsaXRzdGFydAogICAgICAgIEZNUy0+PkZHUzogY2FsbCBmdF9nZXRfc3BsaXRsZW4KICAgICAgICBGR1MtPj5GUzogVXNlIGZ0X3N1YnN0ciB0byBnZXQgc3BsaXQgcGFydAogICAgICAgIGFsdCBpZiBmdF9zdWJzdHIgZmFpbHMKICAgICAgICAgICAgbm90ZSBvdmVyIEZTOiBmcmVlIHRoZSBtZW1vcnkgYW5kIHJldHVybiBOVUxMCiAgICAgICAgZWxzZSBvdGhlcndpc2UKICAgICAgICAgICAgRlMtPj5GUzogaW5jcmVtZW50IHJlc3VsdF9pCiAgICAgICAgZW5kCiAgICBlbmQKICAgIEZGQS0tPj5GUzogZnJlZSB0aGUgbWVtb3J5CiAgICBGUy0tPj5NOiBSZXR1cm4gcmVzdWx0CmVuZA==
F18: =sheetNameRef!$A6 -> GPT-4-ft_strlen | G18: {=INDEX(INDIRECT("'" & $F18 & "'!$F$2:$F$101"), MATCH(MAX(IF(INDIRECT("'" & $F18 & "'!$A$2:$A$101")=1, INDIRECT("'" & $F18 & "'!$B$2:$B$101"), 0)), INDIRECT("'" & $F18 & "'!$B$2:$B$101"), 0))} -> https://mermaid.ink/img/JSV7aW5pdDp7J3RoZW1lJzonZm9yZXN0J319JSUKc2VxdWVuY2VEaWFncmFtCnBhcnRpY2lwYW50IE0gYXMgbWFpbigpCnBhcnRpY2lwYW50IEZTTCBhcyBmdF9zdHJsZW4oKQpwYXJ0aWNpcGFudCBQRiBhcyBwcmludGYoKQoKbm90ZSBvdmVyIE06IGNoYXIgKnN0ciA9ICIxMjM0NTY3ODkwIgpub3RlIG92ZXIgTTogQ2FsbCBmdF9zdHJsZW4oc3RyKQpNLT4+RlNMOiBmdF9zdHJsZW4oc3RyKQpub3RlIG92ZXIgRlNMOiBpbml0aWFsaXplIHNpemVfdCBpID0gMApsb29wIHdoaWxlIHN0cltpXSAhPSAnXDAnCiAgICBGU0wtPj5GU0w6IGluY3JlbWVudCBpCmVuZApGU0wtLT4+TTogcmV0dXJuIGkKbm90ZSBvdmVyIE06IGludCBpID0gcmVzdWx0IGZyb20gZnRfc3RybGVuCm5vdGUgb3ZlciBNOiBDYWxsIHByaW50ZigiWyVzXSBpcyAlZC5cbiIsIHN0ciwgaSkKTS0+PlBGOiBwcmludGYoIlslc10gaXMgJWQuXG4iLCBzdHIsIGkpClBGLS0+Pk06IFByaW50IHRoZSByZXN1bHQK
F19: =sheetNameRef!$A7 -> GPT-4-ft_bzero | G19: {=INDEX(INDIRECT("'" & $F19 & "'!$F$2:$F$101"), MATCH(MAX(IF(INDIRECT("'" & $F19 & "'!$A$2:$A$101")=1, INDIRECT("'" & $F19 & "'!$B$2:$B$101"), 0)), INDIRECT("'" & $F19 & "'!$B$2:$B$101"), 0))} -> https://mermaid.ink/img/JSV7aW5pdDp7J3RoZW1lJzonZm9yZXN0J319JSUKc2VxdWVuY2VEaWFncmFtCnBhcnRpY2lwYW50IE0gYXMgbWFpbigpCnBhcnRpY2lwYW50IEZNQiBhcyBmdF9iemVybygpCnBhcnRpY2lwYW50IEZNUyBhcyBmdF9tZW1zZXQoKQpwYXJ0aWNpcGFudCBQRiBhcyBwcmludGYoKQoKbm90ZSBvdmVyIE06IGNoYXIgc3RyW10gaXMgaW5pdGlhbGl6ZWQgd2l0aCAiMTIzNDU2Nzg5MCIKbm90ZSBvdmVyIE06IGkgaXMgaW5pdGlhbGl6ZWQgd2l0aCAwCk0tPj5GTUI6IENhbGwgZnRfYnplcm8oc3RyLCA1KQpGTUItPj5GTVM6IENhbGwgZnRfbWVtc2V0KHMsIDAsIGxlbikKbm90ZSBvdmVyIEZNUzogSW5pdGlhbGl6ZSBwdHIgdG8gcG9pbnQgdG8gZHN0Cmxvb3Agd2hpbGUgbGVuID4gMAogICAgbm90ZSBvdmVyIEZNUzogU2V0ICpwdHIgdG8gdmFsIGFuZCBpbmNyZW1lbnQgcHRyCiAgICBGTVMtPj5GTVM6IERlY3JlbWVudCBsZW4gYnkgMQplbmQKRk1TLS0+PkZNQjogUmV0dXJuIGRzdApGTUItLT4+TTogUmV0dXJuIGZyb20gZnRfYnplcm8KbG9vcCBpIDwgMTAKICAgIGFsdCBpZiBzdHJbaV0gPT0gJ1wwJwogICAgICAgIE0tPj5QRjogQ2FsbCBwcmludGYoIjBcbiIpCiAgICAgICAgbm90ZSBvdmVyIFBGOiBQcmludCAiMCIKICAgIGVsc2UgT3RoZXJ3aXNlCiAgICAgICAgTS0+PlBGOiBDYWxsIHByaW50ZigiJWNcbiIsIHN0cltpXSkKICAgICAgICBub3RlIG92ZXIgUEY6IFByaW50IHRoZSBjaGFyYWN0ZXIgaW4gc3RyW2ldCiAgICBlbmQKICAgIG5vdGUgb3ZlciBNOiBJbmNyZW1lbnQgaSBieSAxCmVuZA==
F20: =sheetNameRef!$A8 -> GPT-4-ft_memmove | G20: {=INDEX(INDIRECT("'" & $F20 & "'!$F$2:$F$101"), MATCH(MAX(IF(INDIRECT("'" & $F20 & "'!$A$2:$A$101")=1, INDIRECT("'" & $F20 & "'!$B$2:$B$101"), 0)), INDIRECT("'" & $F20 & "'!$B$2:$B$101"), 0))} -> https://mermaid.ink/img/JSV7aW5pdDp7J3RoZW1lJzonZm9yZXN0J319JSUKc2VxdWVuY2VEaWFncmFtCnBhcnRpY2lwYW50IE0gYXMgbWFpbigpCnBhcnRpY2lwYW50IEZNTSBhcyBmdF9tZW1tb3ZlKCkKcGFydGljaXBhbnQgRk1DUCBhcyBmdF9tZW1jcHkoKQpwYXJ0aWNpcGFudCBQRiBhcyBwcmludGYoKQpub3RlIG92ZXIgTTogY2hhciBzcmNbXSBpbml0aWFsaXplZApub3RlIG92ZXIgTTogY2hhciBkZXN0WzUwXSBpbml0aWFsaXplZApNLT4+Rk1NOiBDYWxsIGZ0X21lbW1vdmUoZGVzdCwgc3JjLCAxMSkKbm90ZSBvdmVyIEZNTTogdW5zaWduZWQgY2hhciAqZCwgKnMgaW5pdGlhbGl6ZWQKYWx0IGlmIGQgPT0gcwogICAgRk1NLS0+Pk06IHJldHVybiBkc3QKZWxzZSBpZiBkIDwgcwogICAgRk1NLT4+Rk1DUDogQ2FsbCBmdF9tZW1jcHkoZCwgcywgbGVuKQogICAgbm90ZSBvdmVyIEZNQ1A6IHVuc2lnbmVkIGNoYXIgKnB0ciBpbml0aWFsaXplZAogICAgYWx0IGlmIGRzdCA9PSBzcmMKICAgICAgICBGTUNQLS0+PkZNTTogcmV0dXJuIGRzdAogICAgZWxzZSBXaGlsZSBsZW4tLSA+IDAKICAgICAgICBsb29wIENvcHkgYnl0ZSBieSBieXRlCiAgICAgICAgICAgIG5vdGUgb3ZlciBGTUNQOiAqcHRyKysgPSAqKHVuc2lnbmVkIGNoYXIgKilzcmMrKwogICAgICAgIGVuZAogICAgZW5kCiAgICBGTUNQLS0+PkZNTTogcmV0dXJuIGRzdAplbHNlIE90aGVyd2lzZSBDb3B5IGZyb20gZW5kIGlmIGQgPiBzCiAgICBhbHQgd2hpbGUgbGVuID4gMAogICAgICAgIGxvb3AgQ29weSBieXRlIGJ5IGJ5dGUgYmFja3dhcmRzCiAgICAgICAgICAgIG5vdGUgb3ZlciBGTU06ICooZCArIChsZW4gLSAxKSkgPSAqKHVuc2lnbmVkIGNoYXIgKikocyArIChsZW4gLSAxKSkKICAgICAgICAgICAgRk1NLT4+Rk1NOiBkZWNyZW1lbnQgbGVuCiAgICAgICAgZW5kCiAgICBlbmQKZW5kCkZNTS0tPj5NOiBSZXR1cm4gZHN0IHBvaW50ZXIgYWZ0ZXIgbWVtbW92ZQpNLT4+UEY6IENhbGwgcHJpbnRmKCJjb3BpZWQgc3RyaW5nIDogJXNcbiIsIGRlc3QpClBGLS0+Pk06IEZ1bmN0aW9uIHByaW50cyB0aGUgY29waWVkIHN0cmluZwpub3RlIG92ZXIgTTogUmV0dXJuIDAgKGV4aXQgbWFpbigpKQ==
F21: =sheetNameRef!$A9 -> GPT-4-ft_atoi | G21: {=INDEX(INDIRECT("'" & $F21 & "'!$F$2:$F$101"), MATCH(MAX(IF(INDIRECT("'" & $F21 & "'!$A$2:$A$101")=1, INDIRECT("'" & $F21 & "'!$B$2:$B$101"), 0)), INDIRECT("'" & $F21 & "'!$B$2:$B$101"), 0))} -> https://mermaid.ink/img/JSV7aW5pdDp7J3RoZW1lJzonZm9yZXN0J319JSUKc2VxdWVuY2VEaWFncmFtCnBhcnRpY2lwYW50IG1haW4gYXMgbWFpbigpCnBhcnRpY2lwYW50IGZ0X2lzZGlnaXQgYXMgZnRfaXNkaWdpdCgpCnBhcnRpY2lwYW50IGZ0X2lzc3BhY2UgYXMgZnRfaXNzcGFjZSgpCnBhcnRpY2lwYW50IGZ0X2lzb3ZlcmZsb3cgYXMgZnRfaXNvdmVyZmxvdygpCnBhcnRpY2lwYW50IGZ0X2F0b2kgYXMgZnRfYXRvaSgpCnBhcnRpY2lwYW50IHByaW50ZiBhcyBwcmludGYoKQoKbm90ZSBvdmVyIG1haW46IGNoYXIgKnN0ciA9ICIxMjM0NTY3ODkwIgptYWluLT4+ZnRfYXRvaTogQ2FsbCBmdF9hdG9pKHN0cikKbm90ZSBvdmVyIGZ0X2F0b2k6IGxvbmcgbnVtID0gMFxuaW50IGlzX25lZyA9IDAKbG9vcCB1bnRpbCBub3QgZnRfaXNzcGFjZSgqc3RyKQogICAgZnRfYXRvaS0+PmZ0X2lzc3BhY2U6IENhbGwgZnRfaXNzcGFjZSgqc3RyKQogICAgYWx0IGZ0X2lzc3BhY2UoKSB0cnVlCiAgICAgICAgbm90ZSBvdmVyIGZ0X2lzc3BhY2U6IFJldHVybnMgMSwgY29udGludWUKICAgIGVsc2UgZnRfaXNzcGFjZSgpIGZhbHNlCiAgICAgICAgbm90ZSBvdmVyIGZ0X2lzc3BhY2U6IFJldHVybnMgMCwgZXhpdCBsb29wCiAgICBlbmQKICAgIGZ0X2lzc3BhY2UtLT4+ZnRfYXRvaTogUmV0dXJuIGNvbnRyb2wKZW5kCmFsdCBzdHIgPT0gJy0nCiAgICBub3RlIG92ZXIgZnRfYXRvaTogaXNfbmVnID0gMQplbHNlIHN0ciA9PSAnKycgb3IgZGlnaXQKICAgIG5vdGUgb3ZlciBmdF9hdG9pOiBDb250aW51ZSB3aXRob3V0IGNoYW5nZQplbmQKbG9vcCB1bnRpbCBub3QgZnRfaXNkaWdpdCgqc3RyKQogICAgZnRfYXRvaS0+PmZ0X2lzZGlnaXQ6IENhbGwgZnRfaXNkaWdpdCgqc3RyKQogICAgYWx0IGZ0X2lzZGlnaXQoKSB0cnVlCiAgICAgICAgbm90ZSBvdmVyIGZ0X2lzZGlnaXQ6IFJldHVybnMgMQogICAgICAgIGZ0X2F0b2ktPj5mdF9pc292ZXJmbG93OiBmdF9pc292ZXJmbG93KCZudW0sIGlzX25lZywgKnN0ciAtICcwJykKICAgICAgICBhbHQgZnRfaXNvdmVyZmxvdygpIHRydWUKICAgICAgICAgICAgbm90ZSBvdmVyIGZ0X2lzb3ZlcmZsb3c6IFJldHVybnMgMSwgbnVtIHNldCB0byBMT05HX01BWCBvciBMT05HX01JTgogICAgICAgICAgICBmdF9pc292ZXJmbG93LS0+PmZ0X2F0b2k6IEJyZWFrIGxvb3AKICAgICAgICBlbHNlIGZ0X2lzb3ZlcmZsb3coKSBmYWxzZQogICAgICAgICAgICBub3RlIG92ZXIgZnRfaXNvdmVyZmxvdzogUmV0dXJucyAwLCBjb250aW51ZQogICAgICAgICAgICBub3RlIG92ZXIgZnRfYXRvaTogbnVtID0gbnVtICogMTAgKyAoKnN0cisrIC0gJzAnKQogICAgICAgIGVuZAogICAgICAgIGZ0X2lzb3ZlcmZsb3ctLT4+ZnRfYXRvaTogUmV0dXJuCiAgICBlbHNlIGZ0X2lzZGlnaXQoKSBmYWxzZQogICAgICAgIG5vdGUgb3ZlciBmdF9pc2RpZ2l0OiBSZXR1cm5zIDAsIGV4aXQgbG9vcAogICAgZW5kCiAgICBmdF9pc2RpZ2l0LS0+PmZ0X2F0b2k6IFJldHVybiBjb250cm9sCmVuZAphbHQgaWYgaXNfbmVnCiAgICBmdF9hdG9pLS0+Pm1haW46IFJldHVybiAtbnVtCmVsc2UKICAgIGZ0X2F0b2ktLT4+bWFpbjogUmV0dXJuIG51bQplbmQKbm90ZSBvdmVyIG1haW46IGludCBpID0gZnRfYXRvaShzdHIpCm1haW4tPj5wcmludGY6IENhbGwgcHJpbnRmKCIlZFxuIiwgaSkKcHJpbnRmLS0+Pm1haW46IFByaW50IHRoZSByZXN1bHQ=
F22: =sheetNameRef!$A10 -> GPT-4-ft_split | G22: {=INDEX(INDIRECT("'" & $F22 & "'!$F$2:$F$101"), MATCH(MAX(IF(INDIRECT("'" & $F22 & "'!$A$2:$A$101")=1, INDIRECT("'" & $F22 & "'!$B$2:$B$101"), 0)), INDIRECT("'" & $F22 & "'!$B$2:$B$101"), 0))} -> https://mermaid.ink/img/JSV7aW5pdDp7J3RoZW1lJzonZm9yZXN0J319JSUKc2VxdWVuY2VEaWFncmFtCnBhcnRpY2lwYW50IE0gYXMgbWFpbigpCnBhcnRpY2lwYW50IEZTIGFzIGZ0X3NwbGl0KCkKcGFydGljaXBhbnQgRkdTIGFzIGZ0X2dldF9zcGxpdHRpbWVzKCkKcGFydGljaXBhbnQgRk1TIGFzIGZ0X21vdmVfc3BsaXRzdGFydCgpCnBhcnRpY2lwYW50IEZHTCBhcyBmdF9nZXRfc3BsaXRsZW4oKQpwYXJ0aWNpcGFudCBGU1MgYXMgZnRfc3Vic3RyKCkKcGFydGljaXBhbnQgRlNMRU4gYXMgZnRfc3RybGVuKCkKcGFydGljaXBhbnQgRkNQWSBhcyBmdF9tZW1jcHkoKQpwYXJ0aWNpcGFudCBGRkEgYXMgZnRfZnJlZV9hcnJheSgpCnBhcnRpY2lwYW50IFBNIGFzIHByaW50ZigpCgpub3RlIG92ZXIgTTogY2hhciAqKnJlc3VsdApub3RlIG92ZXIgTTogY2hhciAqc3RyID0gInNwbGl0ICB8fHRoaXN8Zm9yfG1lfHx8fHwhfCIgCm5vdGUgb3ZlciBNOiBjaGFyIGMgPSAnfCcKCk0tPj5GUzogQ2FsbCBmdF9zcGxpdChzdHIsIGMpCm5vdGUgb3ZlciBGUzogSW5pdGlhbGl6ZSByZXN1bHRfaSA9IDAKbm90ZSBvdmVyIEZTOiBJbml0aWFsaXplIHNwbGl0X2NvdW50ID0gZnRfZ2V0X3NwbGl0dGltZXMoc3RyLCBjKQpGUy0+PkZHUzogQ2FsbCBmdF9nZXRfc3BsaXR0aW1lcyhzdHIsIGMpCmxvb3Agd2hpbGUgKnN0ciAhPSAnXDAnCiAgICBub3RlIG92ZXIgRkdTOiBjb3VudCA9IGZ0X21vdmVfc3BsaXRzdGFydChzdHIsIGMpCiAgICBGR1MtPj5GTVM6IENhbGwgZnRfbW92ZV9zcGxpdHN0YXJ0KHN0ciwgYykKICAgIGxvb3Agd2hpbGUgc3RyW2NvdW50XSBpcyBkZWxpbWl0ZXIKICAgICAgICBGTVMtPj5GTVM6IGluY3JlbWVudCBjb3VudAogICAgZW5kCiAgICBub3RlIG92ZXIgRkdTOiBzdHIgKz0gY291bnQgKHNraXAgZGVsaW1pdGVycykKICAgIGFsdCBpZiAqc3RyID09ICdcMCcKICAgICAgICBub3RlIG92ZXIgRkdTOiBCcmVhayAoZW5kIG9mIHN0cmluZyBmb3VuZCkKICAgIGVsc2UgT3RoZXJ3aXNlCiAgICAgICAgbm90ZSBvdmVyIEZHUzogY291bnQgPSBmdF9nZXRfc3BsaXRsZW4oc3RyLCBjKQogICAgICAgIEZHUy0+PkZHTDogQ2FsbCBmdF9nZXRfc3BsaXRsZW4oc3RyLCBjKQogICAgICAgIGxvb3Agd2hpbGUgc3RyW2NvdW50XSBpcyBub3QgZGVsaW1pdGVyCiAgICAgICAgICAgIEZHTC0+PkZHTDogaW5jcmVtZW50IGNvdW50CiAgICAgICAgZW5kCiAgICAgICAgbm90ZSBvdmVyIEZHUzogZWxlbSsrIChjb3VudCBhIG5vbi1lbXB0eSBzdHJpbmcpCiAgICAgICAgbm90ZSBvdmVyIEZHUzogc3RyICs9IGNvdW50IChtb3ZlIHRvIG5leHQgc2VnbWVudCkKICAgIGVuZAplbmQKRkdTLS0+PkZTOiByZXR1cm4gZWxlbSAoTnVtYmVyIG9mIHNlZ21lbnRzKQoKYWx0IGlmICFyZXN1bHQgKG1hbGxvYyBmYWlsKQogICAgRlMtLT4+TTogcmV0dXJuIE5VTEwKZWxzZSBPdGhlcndpc2UKICAgIGxvb3Agd2hpbGUgcmVzdWx0X2kgPCBzcGxpdF9jb3VudAogICAgICAgIG5vdGUgb3ZlciBGUzogc3RyICs9IGZ0X21vdmVfc3BsaXRzdGFydChzdHIsIGMpIChTa2lwIGRlbGltaXRlcnMpCiAgICAgICAgRlMtPj5GTVM6IENhbGwgZnRfbW92ZV9zcGxpdHN0YXJ0KHN0ciwgYykKICAgICAgICBsb29wIHdoaWxlIHN0cltjb3VudF0gaXMgZGVsaW1pdGVyCiAgICAgICAgICAgIEZNUy0+PkZNUzogaW5jcmVtZW50IGNvdW50CiAgICAgICAgZW5kCiAgICAgICAgbm90ZSBvdmVyIEZTOiBzcGxpdF9sZW4gPSBmdF9nZXRfc3BsaXRsZW4oc3RyLCBjKQogICAgICAgIEZTLT4+RkdMOiBDYWxsIGZ0X2dldF9zcGxpdGxlbihzdHIsIGMpCiAgICAgICAgbG9vcCB3aGlsZSBzdHJbY291bnRdIGlzIG5vdCBkZWxpbWl0ZXIKICAgICAgICAgICAgRkdMLT4+RkdMOiBpbmNyZW1lbnQgY291bnQKICAgICAgICBlbmQKICAgICAgICBub3RlIG92ZXIgRlM6IHJlc3VsdFtyZXN1bHRfaV0gPSBmdF9zdWJzdHIoc3RyLCAwLCBzcGxpdF9sZW4pCiAgICAgICAgRlMtPj5GU1M6IENhbGwgZnRfc3Vic3RyKHN0ciwgMCwgc3BsaXRfbGVuKQogICAgICAgIG5vdGUgb3ZlciBGU1M6IHNpemUgPSBmdF9zdHJsZW4oc3RyKQogICAgICAgIEZTUy0+PkZTTEVOOiBDYWxsIGZ0X3N0cmxlbihzdHIpCiAgICAgICAgbG9vcCB3aGlsZSBzdHJbaV0gIT0gJ1wwJwogICAgICAgICAgICBGU0xFTi0+PkZTTEVOOiBpbmNyZW1lbnQgaQogICAgICAgIGVuZAogICAgICAgIEZTTEVOLS0+PkZTUzogcmV0dXJuIGkKICAgICAgICAKICAgICAgICBhbHQgaWYgc2l6ZSA8PSBzdGFydAogICAgICAgICAgICBub3RlIG92ZXIgRlNTOiBzaXplID0gMAogICAgICAgIGVsc2UgT3RoZXJ3aXNlCiAgICAgICAgICAgIG5vdGUgb3ZlciBGU1M6IHNpemUgPSBzaXplIC0gc3RhcnQKICAgICAgICAgICAgYWx0IGlmIHNpemUgPiBsZW4KICAgICAgICAgICAgICAgIG5vdGUgb3ZlciBGU1M6IHNpemUgPSBsZW4KICAgICAgICAgICAgZW5kCiAgICAgICAgZW5kCgogICAgICAgIGFsdCBpZiAhcmVzdWx0IChtYWxsb2MgZmFpbCkKICAgICAgICAgICAgRlNTLS0+PkZTOiByZXR1cm4gTlVMTAogICAgICAgIGVsc2UgT3RoZXJ3aXNlCiAgICAgICAgICAgIG5vdGUgb3ZlciBGU1M6IGZ0X21lbWNweShyZXN1bHQsIHN0ciArIHN0YXJ0LCBzaXplKQogICAgICAgICAgICBGU1MtPj5GQ1BZOiBDYWxsIGZ0X21lbWNweShyZXN1bHQsIHN0ciArIHN0YXJ0LCBzaXplKQogICAgICAgICAgICBub3RlIG92ZXIgRkNQWTogcHRyID0gZHN0CiAgICAgICAgICAgIGxvb3Agd2hpbGUgbGVuID4gMAogICAgICAgICAgICAgICAgRkNQWS0+PkZDUFk6IGNvcHkgYnl0ZSBmcm9tIHNyYyB0byBkc3QgYW5kIGluY3JlbWVudCBwb2ludGVycwogICAgICAgICAgICAgICAgbm90ZSBvdmVyIEZDUFk6IGxlbi0tCiAgICAgICAgICAgIGVuZAogICAgICAgICAgICBGQ1BZLS0+PkZTUzogcmV0dXJuIGRzdAogICAgICAgICAgICBub3RlIG92ZXIgRlNTOiAqKHJlc3VsdCArIHNpemUpID0gJ1wwJwogICAgICAgICAgICBGU1MtLT4+RlM6IHJldHVybiByZXN1bHQKICAgICAgICBlbmQKCiAgICAgICAgYWx0IGlmICFyZXN1bHRbcmVzdWx0X2ldCiAgICAgICAgICAgIEZTLT4+RkZBOiBDYWxsIGZ0X2ZyZWVfYXJyYXkocmVzdWx0KQogICAgICAgICAgICBsb29wIHdoaWxlIHJlc3VsdFtpXQogICAgICAgICAgICAgICAgRkZBLT4+RkZBOiBmcmVlKHJlc3VsdFtpXSkgJiBpbmNyZW1lbnQgaQogICAgICAgICAgICBlbmQKICAgICAgICAgICAgRkZBLS0+PkZTOiBmcmVlKHJlc3VsdCkgJiByZXR1cm4gTlVMTAogICAgICAgICAgICBGUy0tPj5NOiByZXR1cm4gTlVMTAogICAgICAgIGVuZAogICAgICAgIAogICAgICAgIG5vdGUgb3ZlciBGUzogc3RyICs9IHNwbGl0X2xlbgogICAgICAgIG5vdGUgb3ZlciBGUzogcmVzdWx0X2krKwogICAgZW5kCmVuZAoKRlMtLT4+TTogcmV0dXJuIHJlc3VsdCAoU3BsaXQgc3RyaW5nIGFycmF5KQoKbm90ZSBvdmVyIE06IFByaW50aW5nIGVhY2ggc3RyaW5nIGluIHJlc3VsdApsb29wIHdoaWxlIHJlc3VsdFtpXQogICAgTS0+PlBNOiBDYWxsIHByaW50ZigiJXNcbiIsIHJlc3VsdFtpXSkKICAgIFBNLS0+Pk06IFByaW50IHRoZSBzdHJpbmcgYXQgcmVzdWx0W2ldCmVuZAo=

Sheet sheetNameRef
A1: GPT-3.5-ft_strlen
A2: GPT-3.5-ft_bzero
A3: GPT-3.5-ft_memmove
A4: GPT-3.5-ft_atoi
A5: GPT-3.5-ft_split
A6: GPT-4-ft_strlen
A7: GPT-4-ft_bzero
A8: GPT-4-ft_memmove
A9: GPT-4-ft_atoi
A10: GPT-4-ft_split
A11: GPT-4-ft_printf
A12: GPT-3.5-errorInput

Sheet promptTest
B1: Rate of three backticks for code blocks included in the response (n=100)
A2: same prompt as GPT-4 | B2: =COUNTIF('GPT-3.5-test0-testInput'!$E$2:$E$101,"```*") -> 96
A3: test1 | B3: =COUNTIF('GPT-3.5-test1-testInput'!$E$2:$E$101,"```*") -> 69
A4: test2 | B4: =COUNTIF('GPT-3.5-test2-testInput'!$E$2:$E$101,"```*") -> 59
A5: test3 | B5: =COUNTIF('GPT-3.5-test3-testInput'!$E$2:$E$101,"```*") -> 6
A6: function calling | B6: =COUNTIF('GPT-3.5-testInput'!$E$2:$E$101,"```*") -> 1

Sheet GPT-3.5-testInput
A1: status | B1: comp | C1: prompt | D1: total | E1: mermaid | F1: url | G1: filename | H1: input
A2: 1 | B2: 140 | C2: 1215 | D2: 1355 | E2: sequenceDiagram participant M as main() participant FSL as ft_strlen() participant FSLCPY as ft_strlcpy() participant PF as printf() M->>FSLCPY: call ft_strlcpy(dst, src, 11) FSLCPY->>FSL: call ft_strlen(src) FSL-->>FSLCPY: return 10 FSLCPY->>PF: call printf("[%s] is %d.\n", dst, 10) PF-->>M: [1234567890] is 10. | F2: https://mermaid.ink/img/JSV7aW5pdDp7J3RoZW1lJzonZm9yZXN0J319JSUKc2VxdWVuY2VEaWFncmFtCnBhcnRpY2lwYW50IE0gYXMgbWFpbigpCnBhcnRpY2lwYW50IEZTTCBhcyBmdF9zdHJsZW4oKQpwYXJ0aWNpcGFudCBGU0xDUFkgYXMgZnRfc3RybGNweSgpCnBhcnRpY2lwYW50IFBGIGFzIHByaW50ZigpCk0tPj5GU0xDUFk6IGNhbGwgZnRfc3RybGNweShkc3QsIHNyYywgMTEpCkZTTENQWS0+PkZTTDogY2FsbCBmdF9zdHJsZW4oc3JjKQpGU0wtLT4+RlNMQ1BZOiByZXR1cm4gMTAKRlNMQ1BZLT4+UEY6IGNhbGwgcHJpbnRmKCJbJXNdIGlzICVkLlxuIiwgZHN0LCAxMCkKUEYtLT4+TTogWzEyMzQ1Njc4OTBdIGlzIDEwLg== | G2: ft_strlcpy | H2: #include <stdio.h> size_t ft_strlen(const char *str) { size_t i; i = 0; while (str[i] != '\0') i++; return (i); } size_t ft_strlcpy(char *dst, const char *src, size_t size) { size_t i; i = 0; if (size > 0) { while (src[i] != '\0' && i < (size - 1)) { dst[i] = src[i]; i++; } dst[i] = '\0'; } return (ft_strlen(src)); } int main() { char *src = "1234567890"; char dst[50]; int i = ft_strlcpy(dst, src, 11); printf("[%s] is %d.\n", dst, i); }
A3: 1 | B3: 192 | C3: 1215 | D3: 1407 | E3: sequenceDiagram participant M as main() participant FSL as ft_strlen() participant FSLC as ft_strlcpy() participant PF as printf() M->>FSLC: Call ft_strlcpy(dst, src, 11) alt if size > 0 FSLC->>FSL: Call ft_strlen(src) FSL-->>FSLC: Return length of src FSLC->>FSLC: Copy characters from src to dst FSLC->>FSLC: Append null character to dst FSLC-->>M: Return length of src else Otherwise FSLC-->>M: Return 0 end M->>PF: call printf("[%s] is %d.\n", dst, i) PF-->>M: Print the result | F3: https://mermaid.ink/img/JSV7aW5pdDp7J3RoZW1lJzonZm9yZXN0J319JSUKc2VxdWVuY2VEaWFncmFtCnBhcnRpY2lwYW50IE0gYXMgbWFpbigpCnBhcnRpY2lwYW50IEZTTCBhcyBmdF9zdHJsZW4oKQpwYXJ0aWNpcGFudCBGU0xDIGFzIGZ0X3N0cmxjcHkoKQpwYXJ0aWNpcGFudCBQRiBhcyBwcmludGYoKQpNLT4+RlNMQzogQ2FsbCBmdF9zdHJsY3B5KGRzdCwgc3JjLCAxMSkKYWx0IGlmIHNpemUgPiAwCkZTTEMtPj5GU0w6IENhbGwgZnRfc3RybGVuKHNyYykKRlNMLS0+PkZTTEM6IFJldHVybiBsZW5ndGggb2Ygc3JjCkZTTEMtPj5GU0xDOiBDb3B5IGNoYXJhY3RlcnMgZnJvbSBzcmMgdG8gZHN0CkZTTEMtPj5GU0xDOiBBcHBlbmQgbnVsbCBjaGFyYWN0ZXIgdG8gZHN0CkZTTEMtLT4+TTogUmV0dXJuIGxlbmd0aCBvZiBzcmMKZWxzZSBPdGhlcndpc2UKRlNMQy0tPj5NOiBSZXR1cm4gMAplbmQKTS0+PlBGOiBjYWxsIHByaW50ZigiWyVzXSBpcyAlZC5cbiIsIGRzdCwgaSkKUEYtLT4+TTogUHJpbnQgdGhlIHJlc3VsdA== | G3: ft_strlcpy | H3: #include <stdio.h> size_t ft_strlen(const char *str) { size_t i; i = 0; while (str[i] != '\0') i++; return (i); } size_t ft_strlcpy(char *dst, const char *src, size_t size) { size_t i; i = 0; if (size > 0) { while (src[i] != '\0' && i < (size - 1)) { dst[i] = src[i]; i++; } dst[i] = '\0'; } return (ft_strlen(src)); } int main() { char *src = "1234567890"; char dst[50]; int i = ft_strlcpy(dst, src, 11); printf("[%s] is %d.\n", dst, i); }
A4: 1 | B4: 300 | C4: 1215 | D4: 1515 | E4: sequenceDiagram participant M as main() participant FSL as ft_strlen() participant FSLC as ft_strlcpy() participant P as printf() M->>FSLC: call ft_strlcpy(dst, src, 11) FSLC->>P: return (ft_strlen(src)) P-->>M: Print result | F4: https://mermaid.ink/img/JSV7aW5pdDp7J3RoZW1lJzonZm9yZXN0J319JSUKc2VxdWVuY2VEaWFncmFtCiAgICBwYXJ0aWNpcGFudCBNIGFzIG1haW4oKQogICAgcGFydGljaXBhbnQgRlNMIGFzIGZ0X3N0cmxlbigpCiAgICBwYXJ0aWNpcGFudCBGU0xDIGFzIGZ0X3N0cmxjcHkoKQogICAgcGFydGljaXBhbnQgUCBhcyBwcmludGYoKQogICAgCiAgICBNLT4+RlNMQzogY2FsbCBmdF9zdHJsY3B5KGRzdCwgc3JjLCAxMSkKICAgIEZTTEMtPj5QOiByZXR1cm4gKGZ0X3N0cmxlbihzcmMpKQogICAgUC0tPj5NOiBQcmludCByZXN1bHQKICAgIA== | G4: ft_strlcpy | H4: #include <stdio.h> size_t ft_strlen(const char *str) { size_t i; i = 0; while (str[i] != '\0') i++; return (i); } size_t ft_strlcpy(char *dst, const char *src, size_t size) { size_t i; i = 0; if (size > 0) { while (src[i] != '\0' && i < (size - 1)) { dst[i] = src[i]; i++; } dst[i] = '\0'; } return (ft_strlen(src)); } int main() { char *src = "1234567890"; char dst[50]; int i = ft_strlcpy(dst, src, 11); printf("[%s] is %d.\n", dst, i); }
A5: 0 | B5: 198 | C5: 1215 | D5: 1413 | E5: sequenceDiagram participant M as main() participant FSL as ft_strlen() participant FSLC as ft_strlcpy() participant PF as printf() M->>FSLC: call ft_strlcpy(dst, src, 11) note over FSLC: i = 0 alt if size > 0 loop while src[i] != '\0' and i < (size - 1) FSLC->>FSLC: dst[i] = src[i] FSLC->>FSLC: i++ end FSLC->>FSLC: dst[i] = '\0' FSLC-->>M: return ft_strlen(src) M->>PF: call printf("[%s] is %d.\n", dst, i) PF-->>M: Print the result | F5: N/A | G5: ft_strlcpy | H5: #include <stdio.h> size_t ft_strlen(const char *str) { size_t i; i = 0; while (str[i] != '\0') i++; return (i); } size_t ft_strlcpy(char *dst, const char *src, size_t size) { size_t i; i = 0; if (size > 0) { while (src[i] != '\0' && i < (size - 1)) { dst[i] = src[i]; i++; } dst[i] = '\0'; } return (ft_strlen(src)); } int main() { char *src = "1234567890"; char dst[50]; int i = ft_strlcpy(dst, src, 11); printf("[%s] is %d.\n", dst, i); }
A6: 0 | B6: 224 | C6: 1215 | D6: 1439 | E6: sequenceDiagram participant M as main() participant FSL as ft_strlen() participant FSLC as ft_strlcpy() participant PF as printf() M->>FSLC: call ft_strlcpy(dst, src, 11) FSLC->>FSL: call ft_strlen(src) FSL->>FSLC: return i alt if size > 0 note over FSLC: initialize i=0 loop while src[i] != '\0' and i < (size - 1) FSLC->>FSLC: copy src[i] to dst[i] FSLC->>FSLC: increment i end FSLC->>FSLC: set dst[i] = '\0' FSLC-->>M: return ft_strlen(src) M->>PF: call printf("[%s] is %d.\n", dst, i) PF-->>M: Print the result | F6: N/A | G6: ft_strlcpy | H6: #include <stdio.h> size_t ft_strlen(const char *str) { size_t i; i = 0; while (str[i] != '\0') i++; return (i); } size_t ft_strlcpy(char *dst, const char *src, size_t size) { size_t i; i = 0; if (size > 0) { while (src[i] != '\0' && i < (size - 1)) { dst[i] = src[i]; i++; } dst[i] = '\0'; } return (ft_strlen(src)); } int main() { char *src = "1234567890"; char dst[50]; int i = ft_strlcpy(dst, src, 11); printf("[%s] is %d.\n", dst, i); }
A7: 1 | B7: 196 | C7: 1215 | D7: 1411 | E7: sequenceDiagram participant M as main() participant FSL as ft_strlen() participant FSLC as ft_strlcpy() participant PF as printf() M->>FSLC: Call ft_strlcpy(dst, src, 11) alt if size > 0 loop i < (size - 1) and src[i] != '\0' FSLC->>FSLC: dst[i] = src[i] end FSLC->>FSLC: dst[i] = '\0' FSLC-->>M: return ft_strlen(src) else FSLC-->>M: return ft_strlen(src) end M->>PF: call printf("[%s] is %d.\n", dst, i) PF-->>M: Print the result | F7: https://mermaid.ink/img/JSV7aW5pdDp7J3RoZW1lJzonZm9yZXN0J319JSUKc2VxdWVuY2VEaWFncmFtCnBhcnRpY2lwYW50IE0gYXMgbWFpbigpCnBhcnRpY2lwYW50IEZTTCBhcyBmdF9zdHJsZW4oKQpwYXJ0aWNpcGFudCBGU0xDIGFzIGZ0X3N0cmxjcHkoKQpwYXJ0aWNpcGFudCBQRiBhcyBwcmludGYoKQpNLT4+RlNMQzogQ2FsbCBmdF9zdHJsY3B5KGRzdCwgc3JjLCAxMSkKYWx0IGlmIHNpemUgPiAwCiAgICBsb29wIGkgPCAoc2l6ZSAtIDEpIGFuZCBzcmNbaV0gIT0gJ1wwJwogICAgICAgIEZTTEMtPj5GU0xDOiBkc3RbaV0gPSBzcmNbaV0KICAgIGVuZAogICAgRlNMQy0+PkZTTEM6IGRzdFtpXSA9ICdcMCcKICAgIEZTTEMtLT4+TTogcmV0dXJuIGZ0X3N0cmxlbihzcmMpCmVsc2UKICAgIEZTTEMtLT4+TTogcmV0dXJuIGZ0X3N0cmxlbihzcmMpCmVuZApNLT4+UEY6IGNhbGwgcHJpbnRmKCJbJXNdIGlzICVkLlxuIiwgZHN0LCBpKQpQRi0tPj5NOiBQcmludCB0aGUgcmVzdWx0 | G7: ft_strlcpy | H7: #include <stdio.h> size_t ft_strlen(const char *str) { size_t i; i = 0; while (str[i] != '\0') i++; return (i); } size_t ft_strlcpy(char *dst, const char *src, size_t size) { size_t i; i = 0; if (size > 0) { while (src[i] != '\0' && i < (size - 1)) { dst[i] = src[i]; i++; } dst[i] = '\0'; } return (ft_strlen(src)); } int main() { char *src = "1234567890"; char dst[50]; int i = ft_strlcpy(dst, src, 11); printf("[%s] is %d.\n", dst, i); }
A8: 0 | B8: 424 | C8: 1215 | D8: 1639 | E8: sequenceDiagram participant M as main() participant FSL as ft_strlen() participant FSLC as ft_strlcpy() participant PF as printf() M->>main: Enter main->>FSLC: call ft_strlcpy(dst, src, 11) note over FSLC: initialize i = 0 alt if size > 0 FSLC->>FSLC: Copy characters from src to dst FSLC->>FSL: Call ft_strlen(src) note over FSLC: Return result of ft_strlen(src) FSL-->>FSLC: Return length of src FSLC-->>main: Return i main->>PF: Call printf("[%s] is %d.", dst, i) PF-->>main: Print the result | F8: N/A | G8: ft_strlcpy | H8: #include <stdio.h> size_t ft_strlen(const char *str) { size_t i; i = 0; while (str[i] != '\0') i++; return (i); } size_t ft_strlcpy(char *dst, const char *src, size_t size) { size_t i; i = 0; if (size > 0) { while (src[i] != '\0' && i < (size - 1)) { dst[i] = src[i]; i++; } dst[i] = '\0'; } return (ft_strlen(src)); } int main() { char *src = "1234567890"; char dst[50]; int i = ft_strlcpy(dst, src, 11); printf("[%s] is %d.\n", dst, i); }
A9: 0 | B9: 292 | C9: 1215 | D9: 1507 | E9: sequenceDiagram participant M as main() participant FSLC as ft_strlcpy() participant FSLN as ft_strlen() participant PF as printf() M->>FSLC: Call ft_strlcpy(dst, src, 11) note over FSLC: initialize i = 0 alt if size > 0 loop while src[i] != '\0' && i < (size - 1) FSLC->>FSLC: dst[i] = src[i] FSLC->>FSLC: increment i end note over FSLC: assign dst[i] = '\0' FSLC-->>M: return ft_strlen(src) M->>PF: call printf("[%s] is %d.\n", dst, i) PF-->>M: Print the result | F9: N/A | G9: ft_strlcpy | H9: #include <stdio.h> size_t ft_strlen(const char *str) { size_t i; i = 0; while (str[i] != '\0') i++; return (i); } size_t ft_strlcpy(char *dst, const char *src, size_t size) { size_t i; i = 0; if (size > 0) { while (src[i] != '\0' && i < (size - 1)) { dst[i] = src[i]; i++; } dst[i] = '\0'; } return (ft_strlen(src)); } int main() { char *src = "1234567890"; char dst[50]; int i = ft_strlcpy(dst, src, 11); printf("[%s] is %d.\n", dst, i); }
A10: 1 | B10: 228 | C10: 1215 | D10: 1443 | E10: sequenceDiagram participant M as main() participant FSL as ft_strlen() participant FSLC as ft_strlcpy() participant PF as printf() M->>FSLC: Call ft_strlcpy(dst, src, 11) alt size > 0 FSLC->>FSL: Call ft_strlen(src) FSL->>FSLC: return i FSLC->>FSLC: dst[i] = src[i] loop while src[i] != '\0' and i < (size-1) FSLC->>FSLC: increment i end FSLC->>FSLC: dst[i] = '\0' FSLC-->>M: return ft_strlen(src) else size <= 0 FSLC-->>M: return 0 end M->>PF: Call printf("[%s] is %d.\n", dst, i) PF-->>M: Print the result | F10: https://mermaid.ink/img/JSV7aW5pdDp7J3RoZW1lJzonZm9yZXN0J319JSUKc2VxdWVuY2VEaWFncmFtCnBhcnRpY2lwYW50IE0gYXMgbWFpbigpCnBhcnRpY2lwYW50IEZTTCBhcyBmdF9zdHJsZW4oKQpwYXJ0aWNpcGFudCBGU0xDIGFzIGZ0X3N0cmxjcHkoKQpwYXJ0aWNpcGFudCBQRiBhcyBwcmludGYoKQpNLT4+RlNMQzogQ2FsbCBmdF9zdHJsY3B5KGRzdCwgc3JjLCAxMSkKYWx0IHNpemUgPiAwCkZTTEMtPj5GU0w6IENhbGwgZnRfc3RybGVuKHNyYykKRlNMLT4+RlNMQzogcmV0dXJuIGkKRlNMQy0+PkZTTEM6IGRzdFtpXSA9IHNyY1tpXQpsb29wIHdoaWxlIHNyY1tpXSAhPSAnXDAnIGFuZCBpIDwgKHNpemUtMSkKRlNMQy0+PkZTTEM6IGluY3JlbWVudCBpCmVuZApGU0xDLT4+RlNMQzogZHN0W2ldID0gJ1wwJwpGU0xDLS0+Pk06IHJldHVybiBmdF9zdHJsZW4oc3JjKQplbHNlIHNpemUgPD0gMApGU0xDLS0+Pk06IHJldHVybiAwCmVuZApNLT4+UEY6IENhbGwgcHJpbnRmKCJbJXNdIGlzICVkLlxuIiwgZHN0LCBpKQpQRi0tPj5NOiBQcmludCB0aGUgcmVzdWx0 | G10: ft_strlcpy | H10: #include <stdio.h> size_t ft_strlen(const char *str) { size_t i; i = 0; while (str[i] != '\0') i++; return (i); } size_t ft_strlcpy(char *dst, const char *src, size_t size) { size_t i; i = 0; if (size > 0) { while (src[i] != '\0' && i < (size - 1)) { dst[i] = src[i]; i++; } dst[i] = '\0'; } return (ft_strlen(src)); } int main() { char *src = "1234567890"; char dst[50]; int i = ft_strlcpy(dst, src, 11); printf("[%s] is %d.\n", dst, i); }
A11: 1 | B11: 139 | C11: 1215 | D11: 1354 | E11: sequenceDiagram participant M as main() participant FSL as ft_strlen() participant FSLCPY as ft_strlcpy() participant PF as printf() M->>FSLCPY: call ft_strlcpy(dst, src, 11) alt if size > 0 FSLCPY->>FSL: call ft_strlen(src) FSL->>FSLCPY: return i FSLCPY->>PF: [%s] is i. else Otherwise FSLCPY-->>PF: [%s] is 10. end | F11: https://mermaid.ink/img/JSV7aW5pdDp7J3RoZW1lJzonZm9yZXN0J319JSUKc2VxdWVuY2VEaWFncmFtCnBhcnRpY2lwYW50IE0gYXMgbWFpbigpCnBhcnRpY2lwYW50IEZTTCBhcyBmdF9zdHJsZW4oKQpwYXJ0aWNpcGFudCBGU0xDUFkgYXMgZnRfc3RybGNweSgpCnBhcnRpY2lwYW50IFBGIGFzIHByaW50ZigpCk0tPj5GU0xDUFk6IGNhbGwgZnRfc3RybGNweShkc3QsIHNyYywgMTEpCmFsdCBpZiBzaXplID4gMApGU0xDUFktPj5GU0w6IGNhbGwgZnRfc3RybGVuKHNyYykKRlNMLT4+RlNMQ1BZOiByZXR1cm4gaQpGU0xDUFktPj5QRjogWyVzXSBpcyBpLgplbHNlIE90aGVyd2lzZQpGU0xDUFktLT4+UEY6IFslc10gaXMgMTAuCmVuZA== | G11: ft_strlcpy | H11: #include <stdio.h> size_t ft_strlen(const char *str) { size_t i; i = 0; while (str[i] != '\0') i++; return (i); } size_t ft_strlcpy(char *dst, const char *src, size_t size) { size_t i; i = 0; if (size > 0) { while (src[i] != '\0' && i < (size - 1)) { dst[i] = src[i]; i++; } dst[i] = '\0'; } return (ft_strlen(src)); } int main() { char *src = "1234567890"; char dst[50]; int i = ft_strlcpy(dst, src, 11); printf("[%s] is %d.\n", dst, i); }
A12: 1 | B12: 127 | C12: 1112 | D12: 1239 | E12: sequenceDiagram participant M as main() participant FSL as ft_strlen() participant PF as printf() M->>FSL: Call ft_strlen(str) note over FSL: Initialize i = 0 loop while str[i] != '\0' FSL->>FSL: increment i end FSL-->>M: return i M->>PF: Call printf("[%s] is %d.\n", str, i) PF-->>M: Print the result | F12: https://mermaid.ink/img/JSV7aW5pdDp7J3RoZW1lJzonZm9yZXN0J319JSUKc2VxdWVuY2VEaWFncmFtCnBhcnRpY2lwYW50IE0gYXMgbWFpbigpCnBhcnRpY2lwYW50IEZTTCBhcyBmdF9zdHJsZW4oKQpwYXJ0aWNpcGFudCBQRiBhcyBwcmludGYoKQpNLT4+RlNMOiBDYWxsIGZ0X3N0cmxlbihzdHIpCm5vdGUgb3ZlciBGU0w6IEluaXRpYWxpemUgaSA9IDAKbG9vcCB3aGlsZSBzdHJbaV0gIT0gJ1wwJwogICAgRlNMLT4+RlNMOiBpbmNyZW1lbnQgaQplbmQKRlNMLS0+Pk06IHJldHVybiBpCk0tPj5QRjogQ2FsbCBwcmludGYoIlslc10gaXMgJWQuXG4iLCBzdHIsIGkpClBGLS0+Pk06IFByaW50IHRoZSByZXN1bHQ= | G12: ft_strlen | H12: #include <stdio.h> size_t ft_strlen(const char *str) { size_t i; i = 0; while (str[i] != '\0') i++; return (i); } int main() { char *str = "1234567890"; int i = ft_strlen(str); printf("[%s] is %d.\n", str, i); }
A13: 1 | B13: 161 | C13: 1112 | D13: 1273 | E13: sequenceDiagram participant M as main() participant FL as ft_strlen() participant P as printf() M->>FL: Call ft_strlen(str) FL-->>M: Return i M->>P: Call printf("[%s] is %d.\n", str, i) P-->>M: Print the result | F13: https://mermaid.ink/img/JSV7aW5pdDp7J3RoZW1lJzonZm9yZXN0J319JSUKc2VxdWVuY2VEaWFncmFtCnBhcnRpY2lwYW50IE0gYXMgbWFpbigpCnBhcnRpY2lwYW50IEZMIGFzIGZ0X3N0cmxlbigpCnBhcnRpY2lwYW50IFAgYXMgcHJpbnRmKCkKTS0+PkZMOiBDYWxsIGZ0X3N0cmxlbihzdHIpCkZMLS0+Pk06IFJldHVybiBpCk0tPj5QOiBDYWxsIHByaW50ZigiWyVzXSBpcyAlZC5cbiIsIHN0ciwgaSkKUC0tPj5NOiBQcmludCB0aGUgcmVzdWx0 | G13: ft_strlen | H13: #include <stdio.h> size_t ft_strlen(const char *str) { size_t i; i = 0; while (str[i] != '\0') i++; return (i); } int main() { char *str = "1234567890"; int i = ft_strlen(str); printf("[%s] is %d.\n", str, i); }
... A101: 1 | B101: 211 | C101: 1228 | D101: 1439 | E101: sequenceDiagram participant M as main() participant FSN as ft_strncmp() participant PF as printf() M->>FSN: Call ft_strncmp(str1, str2, 20) loop while len && *s1 && (*s1 == *s2) FSN->>FSN: s1++, s2++, len-- alt if len == 0 FSN-->>M: return 0 (strings are equal) else FSN<->>FSN: return *(unsigned char *) s1 - *(unsigned char *) s2 end end alt if i > 0 PF-->>M: Print str1 is greater than str2 else if i < 0 PF-->>M: Print str1 is less than str2 else PF-->>M: Print str1 is equal to str2 end | F101: https://mermaid.ink/img/JSV7aW5pdDp7J3RoZW1lJzonZm9yZXN0J319JSUKc2VxdWVuY2VEaWFncmFtCnBhcnRpY2lwYW50IE0gYXMgbWFpbigpCnBhcnRpY2lwYW50IEZTTiBhcyBmdF9zdHJuY21wKCkKcGFydGljaXBhbnQgUEYgYXMgcHJpbnRmKCkKTS0+PkZTTjogQ2FsbCBmdF9zdHJuY21wKHN0cjEsIHN0cjIsIDIwKQpsb29wIHdoaWxlIGxlbiAmJiAqczEgJiYgKCpzMSA9PSAqczIpCiAgICBGU04tPj5GU046IHMxKyssIHMyKyssIGxlbi0tCiAgICBhbHQgaWYgbGVuID09IDAKICAgICAgICBGU04tLT4+TTogcmV0dXJuIDAgKHN0cmluZ3MgYXJlIGVxdWFsKQogICAgZWxzZQogICAgICAgIEZTTjwtPj5GU046IHJldHVybiAqKHVuc2lnbmVkIGNoYXIgKikgczEgLSAqKHVuc2lnbmVkIGNoYXIgKikgczIKICAgIGVuZAplbmQKYWx0IGlmIGkgPiAwCiAgICBQRi0tPj5NOiBQcmludCBzdHIxIGlzIGdyZWF0ZXIgdGhhbiBzdHIyCmVsc2UgaWYgaSA8IDAKICAgIFBGLS0+Pk06IFByaW50IHN0cjEgaXMgbGVzcyB0aGFuIHN0cjIKZWxzZQogICAgUEYtLT4+TTogUHJpbnQgc3RyMSBpcyBlcXVhbCB0byBzdHIyCmVuZA== | G101: ft_strncmp | H101: #include <stdio.h> int ft_strncmp(const char *s1, const char *s2, size_t len) { while (len && *s1 && (*s1 == *s2)) { s1++; s2++; len--; } if (len == 0) return (0); else return (*(unsigned char *) s1 - *(unsigned char *) s2); } int main() { char *str1 = "abcdefghijk"; char *str2 = "ghi"; int i = ft_strncmp(str1, str2, 20); if (i > 0) printf("%s is greater than %s\n", str1, str2); else if (i < 0) printf("%s is less than %s\n", str1, str2); else printf("%s is equal to %s\n", str1, str2); }

Sheet GPT-3.5-test0-testInput
A1: status | B1: comp | C1: prompt | D1: total | E1: mermaid | F1: url | G1: filename | H1: input
A2: 0 | B2: 206 | C2: 1176 | D2: 1382 | E2: sequenceDiagram participant main as main() participant SL as ft_strlen() participant FSL as ft_strlcpy() participant PF as printf() main->>FSL: Call ft_strlcpy(dst, src, 11) FSL->>SL: Call ft_strlen(src) note over SL: initialize i = 0 loop while src[i] != '\0' alt if size > 0 loop while src[i] != '\0' and i < (size - 1) FSL->FSL: Copy src[i] to dst[i] end FSL->FSL: Append '\0' to dst else size <= 0 note over FSL: Do nothing end SL-->>FSL: Return length of src FSL-->>main: Return length of src main->>PF: Call printf("[%s] is %d.\n", dst, i) PF-->>main: Print the result | F2: N/A | G2: ft_strlcpy | H2: #include <stdio.h> size_t ft_strlen(const char *str) { size_t i; i = 0; while (str[i] != '\0') i++; return (i); } size_t ft_strlcpy(char *dst, const char *src, size_t size) { size_t i; i = 0; if (size > 0) { while (src[i] != '\0' && i < (size - 1)) { dst[i] = src[i]; i++; } dst[i] = '\0'; } return (ft_strlen(src)); } int main() { char *src = "1234567890"; char dst[50]; int i = ft_strlcpy(dst, src, 11); printf("[%s] is %d.\n", dst, i); }
A3: 0 | B3: 211 | C3: 1176 | D3: 1387 | E3: ```sequenceDiagram participant main as main() participant FSL as ft_strlen() participant FSLCPY as ft_strlcpy() participant PF as printf() main->>FSLCPY: Call ft_strlcpy(dst, src, 11) alt if size > 0 FSLCPY->>FSL: Call ft_strlen(src) FSL-->>FSLCPY: Return length of src loop while src[i] != '\0' and i < (size - 1) FSLCPY->>FSLCPY: Copy src[i] to dst[i] end FSLCPY->>FSLCPY: Add '\0' to the end of dst else note over FSLCPY: Do nothing end FSLCPY-->>main: Return length of src main->>PF: Call printf("[%s] is %d.\n", dst, i) PF-->>main: Print the result ``` | F3: N/A | G3: ft_strlcpy | H3: #include <stdio.h> size_t ft_strlen(const char *str) { size_t i; i = 0; while (str[i] != '\0') i++; return (i); } size_t ft_strlcpy(char *dst, const char *src, size_t size) { size_t i; i = 0; if (size > 0) { while (src[i] != '\0' && i < (size - 1)) { dst[i] = src[i]; i++; } dst[i] = '\0'; } return (ft_strlen(src)); } int main() { char *src = "1234567890"; char dst[50]; int i = ft_strlcpy(dst, src, 11); printf("[%s] is %d.\n", dst, i); }
A4: 1 | B4: 190 | C4: 1176 | D4: 1366 | E4: sequenceDiagram participant main as main() participant FSL as ft_strlen() participant FSLC as ft_strlcpy() participant printf as printf() main->>FSLC: Call ft_strlcpy(dst, src, 11) alt size > 0 FSLC->>FSL: Call ft_strlen(src) note over FSL: i = 0 loop while src[i] != '\0' && i < (size - 1) FSLC->>FSLC: dst[i] = src[i] FSLC->>FSLC: increment i end FSLC->>FSLC: dst[i] = '\0' FSLC-->>main: return ft_strlen(src) else main-->>printf: Print error message end main->>printf: Print the result [dst] is i. | F4: https://mermaid.ink/img/JSV7aW5pdDp7J3RoZW1lJzonZm9yZXN0J319JSUKc2VxdWVuY2VEaWFncmFtCnBhcnRpY2lwYW50IG1haW4gYXMgbWFpbigpCnBhcnRpY2lwYW50IEZTTCBhcyBmdF9zdHJsZW4oKQpwYXJ0aWNpcGFudCBGU0xDIGFzIGZ0X3N0cmxjcHkoKQpwYXJ0aWNpcGFudCBwcmludGYgYXMgcHJpbnRmKCkKbWFpbi0+PkZTTEM6IENhbGwgZnRfc3RybGNweShkc3QsIHNyYywgMTEpCmFsdCBzaXplID4gMAogICAgRlNMQy0+PkZTTDogQ2FsbCBmdF9zdHJsZW4oc3JjKQogICAgbm90ZSBvdmVyIEZTTDogaSA9IDAKICAgIGxvb3Agd2hpbGUgc3JjW2ldICE9ICdcMCcgJiYgaSA8IChzaXplIC0gMSkKICAgICAgICBGU0xDLT4+RlNMQzogZHN0W2ldID0gc3JjW2ldCiAgICAgICAgRlNMQy0+PkZTTEM6IGluY3JlbWVudCBpCiAgICBlbmQKICAgIEZTTEMtPj5GU0xDOiBkc3RbaV0gPSAnXDAnCiAgICBGU0xDLS0+Pm1haW46IHJldHVybiBmdF9zdHJsZW4oc3JjKQplbHNlCiAgICBtYWluLS0+PnByaW50ZjogUHJpbnQgZXJyb3IgbWVzc2FnZQplbmQKbWFpbi0+PnByaW50ZjogUHJpbnQgdGhlIHJlc3VsdCBbZHN0XSBpcyBpLg== | G4: ft_strlcpy | H4: #include <stdio.h> size_t ft_strlen(const char *str) { size_t i; i = 0; while (str[i] != '\0') i++; return (i); } size_t ft_strlcpy(char *dst, const char *src, size_t size) { size_t i; i = 0; if (size > 0) { while (src[i] != '\0' && i < (size - 1)) { dst[i] = src[i]; i++; } dst[i] = '\0'; } return (ft_strlen(src)); } int main() { char *src = "1234567890"; char dst[50]; int i = ft_strlcpy(dst, src, 11); printf("[%s] is %d.\n", dst, i); }
A5: 0 | B5: 212 | C5: 1176 | D5: 1388 | E5: ```plaintext sequenceDiagram participant main participant FSL as ft_strlen participant FSLC as ft_strlcpy participant PF as printf main->>FSLC: Call ft_strlcpy(dst, src, 11) note over FSLC: initialize i = 0 alt if size > 0 loop while src[i] != '\0' and i < (size - 1) FSLC->>FSLC: copy src[i] to dst[i] FSLC->>FSLC: increment i end FSLC->>FSLC: assign '\0' to dst[i] FSLC-->>main: return ft_strlen(src) else note over FSLC: No operation is performed FSLC-->>main: return ft_strlen(src) end main->>PF: Call printf("[%s] is %d.\n", dst, i) PF-->>main: Print the result ``` | F5: N/A | G5: ft_strlcpy | H5: #include <stdio.h> size_t ft_strlen(const char *str) { size_t i; i = 0; while (str[i] != '\0') i++; return (i); } size_t ft_strlcpy(char *dst, const char *src, size_t size) { size_t i; i = 0; if (size > 0) { while (src[i] != '\0' && i < (size - 1)) { dst[i] = src[i]; i++; } dst[i] = '\0'; } return (ft_strlen(src)); } int main() { char *src = "1234567890"; char dst[50]; int i = ft_strlcpy(dst, src, 11); printf("[%s] is %d.\n", dst, i); }
A6: 0 | B6: 7 | C6: 1176 | D6: 1183 | E6: ```plaintext input_error ``` | F6: N/A | G6: ft_strlcpy | H6: #include <stdio.h> size_t ft_strlen(const char *str) { size_t i; i = 0; while (str[i] != '\0') i++; return (i); } size_t ft_strlcpy(char *dst, const char *src, size_t size) { size_t i; i = 0; if (size > 0) { while (src[i] != '\0' && i < (size - 1)) { dst[i] = src[i]; i++; } dst[i] = '\0'; } return (ft_strlen(src)); } int main() { char *src = "1234567890"; char dst[50]; int i = ft_strlcpy(dst, src, 11); printf("[%s] is %d.\n", dst, i); }
A7: 0 | B7: 141 | C7: 1176 | D7: 1317 | E7: ```sequenceDiagram participant main participant FSL as ft_strlen participant FSLC as ft_strlcpy participant PF as printf main->>FSLC: Call ft_strlcpy(dst, src, 11) FSLC->>FSL: Call ft_strlen(src) FSL-->>FSLC: Return length of src alt size > 0 FSLC->>FSLC: Copy characters from src to dst note over FSLC: Add null-terminator FSLC-->>main: Return length of src main->>PF: Print [dst] and length PF-->>main: Print result ``` | F7: N/A | G7: ft_strlcpy | H7: #include <stdio.h> size_t ft_strlen(const char *str) { size_t i; i = 0; while (str[i] != '\0') i++; return (i); } size_t ft_strlcpy(char *dst, const char *src, size_t size) { size_t i; i = 0; if (size > 0) { while (src[i] != '\0' && i < (size - 1)) { dst[i] = src[i]; i++; } dst[i] = '\0'; } return (ft_strlen(src)); } int main() { char *src = "1234567890"; char dst[50]; int i = ft_strlcpy(dst, src, 11); printf("[%s] is %d.\n", dst, i); }
A8: 0 | B8: 201 | C8: 1176 | D8: 1377 | E8: ```plaintext sequenceDiagram participant M as main() participant FSL as ft_strlen() participant FSC as ft_strlcpy() participant PF as printf() M->>FSC: call ft_strlcpy(dst, src, 11) FSC->>FSL: call ft_strlen(src) FSL-->>FSC: return length of src alt if size > 0 loop while src[i] != '\0' and i < (size - 1) FSC->>FSC: copy src[i] to dst[i] FSC->>FSC: increment i end FSC->>FSC: set dst[i] as '\0' else FSC-->>M: return length of src end FSC-->>M: return i M->>PF: call printf("[%s] is %d.\n", dst, i) PF-->>M: print the result ``` | F8: N/A | G8: ft_strlcpy | H8: #include <stdio.h> size_t ft_strlen(const char *str) { size_t i; i = 0; while (str[i] != '\0') i++; return (i); } size_t ft_strlcpy(char *dst, const char *src, size_t size) { size_t i; i = 0; if (size > 0) { while (src[i] != '\0' && i < (size - 1)) { dst[i] = src[i]; i++; } dst[i] = '\0'; } return (ft_strlen(src)); } int main() { char *src = "1234567890"; char dst[50]; int i = ft_strlcpy(dst, src, 11); printf("[%s] is %d.\n", dst, i); }
A9: 0 | B9: 181 | C9: 1176 | D9: 1357 | E9: ```sequenceDiagram participant main participant ft_strlcpy participant ft_strlen participant printf main->>ft_strlcpy: Call ft_strlcpy(dst, src, 11) alt if size > 0 loop through src ft_strlcpy->>ft_strlen: Call ft_strlen(src) ft_strlcpy->>ft_strlen: Call ft_strlen(src) end note over ft_strlcpy: Copy character to dst alt if src is not null ft_strlcpy->>ft_strlen: Call ft_strlen(src) else ft_strlcpy->>ft_strlen: Call ft_strlen(src) end ft_strlcpy-->>main: return i main->>printf: Call printf("[%s] is %d.\n", dst, i) printf-->>main: Print the result ``` | F9: N/A | G9: ft_strlcpy | H9: #include <stdio.h> size_t ft_strlen(const char *str) { size_t i; i = 0; while (str[i] != '\0') i++; return (i); } size_t ft_strlcpy(char *dst, const char *src, size_t size) { size_t i; i = 0; if (size > 0) { while (src[i] != '\0' && i < (size - 1)) { dst[i] = src[i]; i++; } dst[i] = '\0'; } return (ft_strlen(src)); } int main() { char *src = "1234567890"; char dst[50]; int i = ft_strlcpy(dst, src, 11); printf("[%s] is %d.\n", dst, i); }
A10: 0 | B10: 193 | C10: 1176 | D10: 1369 | E10: ```plaintext sequenceDiagram participant main participant FSL as ft_strlen participant FSLC as ft_strlcpy participant PF as printf main->>FSLC: Call ft_strlcpy(dst, src, 11) FSLC->>FSL: Call ft_strlen(src) note over FSL: i = 0 loop while str[i] != '\0' FSL-->>FSLC: return i FSLC-->>main: return ft_strlen(src) alt size > 0 FSLC->>FSLC: Copy elements from src to dst FSLC-->>main: return ft_strlen(src) else size <= 0 FSLC-->>main: return ft_strlen(src) end main->>PF: Call printf("[%s] is %d.\n", dst, i) PF-->>main: Print the result ``` | F10: N/A | G10: ft_strlcpy | H10: #include <stdio.h> size_t ft_strlen(const char *str) { size_t i; i = 0; while (str[i] != '\0') i++; return (i); } size_t ft_strlcpy(char *dst, const char *src, size_t size) { size_t i; i = 0; if (size > 0) { while (src[i] != '\0' && i < (size - 1)) { dst[i] = src[i]; i++; } dst[i] = '\0'; } return (ft_strlen(src)); } int main() { char *src = "1234567890"; char dst[50]; int i = ft_strlcpy(dst, src, 11); printf("[%s] is %d.\n", dst, i); }
A11: 0 | B11: 205 | C11: 1176 | D11: 1381 | E11: ```sequenceDiagram participant main as main() participant FSL as ft_strlen() participant FSLC as ft_strlcpy() participant PF as printf() main->>FSLC: Call ft_strlcpy(dst, src, 11) alt size > 0 loop i < (size - 1) and src[i] != '\0' FSLC->>FSL: Call ft_strlen(src) FSL->>FSLC: return length FSLC->>FSLC: assign src[i] to dst[i] end FSLC->>FSLC: assign '\0' to dst[i] FSLC-->>main: return length of src else size <= 0 note over FSLC: No operation, return length of src end main->>PF: Call printf("[%s] is %d.\n", dst, i) PF-->>main: Print the result ``` | F11: N/A | G11: ft_strlcpy | H11: #include <stdio.h> size_t ft_strlen(const char *str) { size_t i; i = 0; while (str[i] != '\0') i++; return (i); } size_t ft_strlcpy(char *dst, const char *src, size_t size) { size_t i; i = 0; if (size > 0) { while (src[i] != '\0' && i < (size - 1)) { dst[i] = src[i]; i++; } dst[i] = '\0'; } return (ft_strlen(src)); } int main() { char *src = "1234567890"; char dst[50]; int i = ft_strlcpy(dst, src, 11); printf("[%s] is %d.\n", dst, i); }
A12: 0 | B12: 77 | C12: 1073 | D12: 1150 | E12: ```plaintext sequenceDiagram participant main as main() participant FL as ft_strlen() participant PF as printf() main->>FL: Call ft_strlen(str) FL-->>main: Return the length of the string main->>PF: Call printf("[%s] is %d.\n", str, i) PF-->>main: Print the returned length and string ``` | F12: N/A | G12: ft_strlen | H12: #include <stdio.h> size_t ft_strlen(const char *str) { size_t i; i = 0; while (str[i] != '\0') i++; return (i); } int main() { char *str = "1234567890"; int i = ft_strlen(str); printf("[%s] is %d.\n", str, i); }
A13: 0 | B13: 104 | C13: 1073 | D13: 1177 | E13: ```sequenceDiagram participant main as main() participant FSL as ft_strlen() participant PF as printf() main->>FSL: Call ft_strlen(str) note over FSL: initialize i = 0 loop while str[i] != '\0' FSL->>FSL: increment i end FSL-->>main: Return i main->>PF: Call printf("[%s] is %d.\n", str, i) PF-->>main: Print the result ``` | F13: N/A | G13: ft_strlen | H13: #include <stdio.h> size_t ft_strlen(const char *str) { size_t i; i = 0; while (str[i] != '\0') i++; return (i); } int main() { char *str = "1234567890"; int i = ft_strlen(str); printf("[%s] is %d.\n", str, i); }
... A101: 0 | B101: 7 | C101: 1086 | D101: 1093 | E101: ```plaintext input_error ``` | F101: N/A | G101: ft_memset | H101: #include <stdio.h> void *ft_memset(void *dst, int val, size_t len) { unsigned char *ptr; ptr = dst; while (len-- > 0) *ptr++ = val; return (dst); } int main() { char str[] = "1234567890"; char *ptr = ft_memset(str, 'a', 5); printf("%s\n", ptr); }

Sheet GPT-3.5-test1-testInput
A1: status | B1: comp | C1: prompt | D1: total | E1: mermaid | F1: url | G1: filename | H1: input
A2: 1 | B2: 209 | C2: 1162 | D2: 1371 | E2: sequenceDiagram participant main as main() participant FSL as ft_strlen() participant FSLCPY as ft_strlcpy() participant PF as printf() main->>FSLCPY: Call ft_strlcpy(dst, src, 11) alt size > 0 note over FSLCPY: initialize i = 0 loop while src[i] != '\0' AND i < (size - 1) FSLCPY->>FSLCPY: dst[i] = src[i] FSLCPY->>FSLCPY: increment i end note over FSLCPY: assign dst[i] = '\0' FSLCPY->>main: Return ft_strlen(src) else size <= 0 note over FSLCPY: return ft_strlen(src) without copying end main->>PF: Call printf("[%s] is %d.\n", dst, i) PF-->>main: Print the result | F2: https://mermaid.ink/img/JSV7aW5pdDp7J3RoZW1lJzonZm9yZXN0J319JSUKc2VxdWVuY2VEaWFncmFtCnBhcnRpY2lwYW50IG1haW4gYXMgbWFpbigpCnBhcnRpY2lwYW50IEZTTCBhcyBmdF9zdHJsZW4oKQpwYXJ0aWNpcGFudCBGU0xDUFkgYXMgZnRfc3RybGNweSgpCnBhcnRpY2lwYW50IFBGIGFzIHByaW50ZigpCm1haW4tPj5GU0xDUFk6IENhbGwgZnRfc3RybGNweShkc3QsIHNyYywgMTEpCmFsdCBzaXplID4gMAogICAgbm90ZSBvdmVyIEZTTENQWTogaW5pdGlhbGl6ZSBpID0gMAogICAgbG9vcCB3aGlsZSBzcmNbaV0gIT0gJ1wwJyBBTkQgaSA8IChzaXplIC0gMSkKICAgICAgICBGU0xDUFktPj5GU0xDUFk6IGRzdFtpXSA9IHNyY1tpXQogICAgICAgIEZTTENQWS0+PkZTTENQWTogaW5jcmVtZW50IGkKICAgIGVuZAogICAgbm90ZSBvdmVyIEZTTENQWTogYXNzaWduIGRzdFtpXSA9ICdcMCcKICAgIEZTTENQWS0+Pm1haW46IFJldHVybiBmdF9zdHJsZW4oc3JjKQplbHNlIHNpemUgPD0gMAogICAgbm90ZSBvdmVyIEZTTENQWTogcmV0dXJuIGZ0X3N0cmxlbihzcmMpIHdpdGhvdXQgY29weWluZwplbmQKbWFpbi0+PlBGOiBDYWxsIHByaW50ZigiWyVzXSBpcyAlZC5cbiIsIGRzdCwgaSkKUEYtLT4+bWFpbjogUHJpbnQgdGhlIHJlc3VsdA== | G2: ft_strlcpy | H2: #include <stdio.h> size_t ft_strlen(const char *str) { size_t i; i = 0; while (str[i] != '\0') i++; return (i); } size_t ft_strlcpy(char *dst, const char *src, size_t size) { size_t i; i = 0; if (size > 0) { while (src[i] != '\0' && i < (size - 1)) { dst[i] = src[i]; i++; } dst[i] = '\0'; } return (ft_strlen(src)); } int main() { char *src = "1234567890"; char dst[50]; int i = ft_strlcpy(dst, src, 11); printf("[%s] is %d.\n", dst, i); }
A3: 1 | B3: 191 | C3: 1162 | D3: 1353 | E3: sequenceDiagram participant main as main() participant FSL as ft_strlen() participant FSLC as ft_strlcpy() participant PF as printf() main->>FSLC: Call ft_strlcpy(dst, src, 11) FSLC->>FSL: Call ft_strlen(src) FSL-->FSLC: Return length of src alt size > 0 loop while src[i] != '\0' && i < (size - 1) FSLC->FSLC: Copy src[i] to dst[i] end FSLC->FSLC: Set dst[i] = '\0' else note over FSLC: No operation end FSLC->>main: Return length of src main->>PF: Call printf("[%s] is %d.\n", dst, i) PF-->>main: Print the result | F3: https://mermaid.ink/img/JSV7aW5pdDp7J3RoZW1lJzonZm9yZXN0J319JSUKc2VxdWVuY2VEaWFncmFtCnBhcnRpY2lwYW50IG1haW4gYXMgbWFpbigpCnBhcnRpY2lwYW50IEZTTCBhcyBmdF9zdHJsZW4oKQpwYXJ0aWNpcGFudCBGU0xDIGFzIGZ0X3N0cmxjcHkoKQpwYXJ0aWNpcGFudCBQRiBhcyBwcmludGYoKQptYWluLT4+RlNMQzogQ2FsbCBmdF9zdHJsY3B5KGRzdCwgc3JjLCAxMSkKRlNMQy0+PkZTTDogQ2FsbCBmdF9zdHJsZW4oc3JjKQpGU0wtLT5GU0xDOiBSZXR1cm4gbGVuZ3RoIG9mIHNyYwphbHQgc2l6ZSA+IDAKICAgIGxvb3Agd2hpbGUgc3JjW2ldICE9ICdcMCcgJiYgaSA8IChzaXplIC0gMSkKICAgICAgICBGU0xDLT5GU0xDOiBDb3B5IHNyY1tpXSB0byBkc3RbaV0KICAgIGVuZAogICAgRlNMQy0+RlNMQzogU2V0IGRzdFtpXSA9ICdcMCcKZWxzZQogICAgbm90ZSBvdmVyIEZTTEM6IE5vIG9wZXJhdGlvbgplbmQKRlNMQy0+Pm1haW46IFJldHVybiBsZW5ndGggb2Ygc3JjCm1haW4tPj5QRjogQ2FsbCBwcmludGYoIlslc10gaXMgJWQuXG4iLCBkc3QsIGkpClBGLS0+Pm1haW46IFByaW50IHRoZSByZXN1bHQK | G3: ft_strlcpy | H3: #include <stdio.h> size_t ft_strlen(const char *str) { size_t i; i = 0; while (str[i] != '\0') i++; return (i); } size_t ft_strlcpy(char *dst, const char *src, size_t size) { size_t i; i = 0; if (size > 0) { while (src[i] != '\0' && i < (size - 1)) { dst[i] = src[i]; i++; } dst[i] = '\0'; } return (ft_strlen(src)); } int main() { char *src = "1234567890"; char dst[50]; int i = ft_strlcpy(dst, src, 11); printf("[%s] is %d.\n", dst, i); }
A4: 0 | B4: 195 | C4: 1162 | D4: 1357 | E4: ```plaintext sequenceDiagram participant main as main() participant FSL as ft_strlen() participant FSLC as ft_strlcpy() participant PF as printf() main->>FSLC: Call ft_strlcpy(dst, src, 11) note over FSLC: initialize i = 0 alt if size > 0 FSLC->>FSL: Call ft_strlen(src) FSLC-->>FSLC: return length of src loop while src[i] != '\0' and i < (size - 1) FSLC->>FSLC: Copy src[i] to dst[i] end FSLC->>FSLC: Set dst[i] to '\0' FSLC-->>main: return length of src main->>PF: Call printf("[%s] is %d.\n", dst, i) PF-->>main: Print the result ``` | F4: N/A | G4: ft_strlcpy | H4: #include <stdio.h> size_t ft_strlen(const char *str) { size_t i; i = 0; while (str[i] != '\0') i++; return (i); } size_t ft_strlcpy(char *dst, const char *src, size_t size) { size_t i; i = 0; if (size > 0) { while (src[i] != '\0' && i < (size - 1)) { dst[i] = src[i]; i++; } dst[i] = '\0'; } return (ft_strlen(src)); } int main() { char *src = "1234567890"; char dst[50]; int i = ft_strlcpy(dst, src, 11); printf("[%s] is %d.\n", dst, i); }
A5: 1 | B5: 225 | C5: 1162 | D5: 1387 | E5: sequenceDiagram participant M as main() participant FSL as ft_strlen() participant FSLS as ft_strlcpy() participant PF as printf() M->>FSLS: Call ft_strlcpy(dst, src, 11) FSLS->>FSL: Call ft_strlen(src) note over FSL: initialize i = 0 loop while src[i] != '\0' FSL->>FSL: increment i end FSL-->>FSLS: return i loop while src[i] != '\0' and i < (size - 1) alt if size > 0 FSLS->>FSLS: copy src[i] to dst[i] FSLS->>FSLS: increment i else note over FSLS: No operation end end FSLS->>FSLS: append '\0' to dst FSLS-->>M: return ft_strlen(src) M->>PF: call printf("[%s] is %d.\n", dst, i) PF-->>M: Print the result | F5: https://mermaid.ink/img/JSV7aW5pdDp7J3RoZW1lJzonZm9yZXN0J319JSUKc2VxdWVuY2VEaWFncmFtCnBhcnRpY2lwYW50IE0gYXMgbWFpbigpCnBhcnRpY2lwYW50IEZTTCBhcyBmdF9zdHJsZW4oKQpwYXJ0aWNpcGFudCBGU0xTIGFzIGZ0X3N0cmxjcHkoKQpwYXJ0aWNpcGFudCBQRiBhcyBwcmludGYoKQpNLT4+RlNMUzogQ2FsbCBmdF9zdHJsY3B5KGRzdCwgc3JjLCAxMSkKRlNMUy0+PkZTTDogQ2FsbCBmdF9zdHJsZW4oc3JjKQpub3RlIG92ZXIgRlNMOiBpbml0aWFsaXplIGkgPSAwCmxvb3Agd2hpbGUgc3JjW2ldICE9ICdcMCcKICAgIEZTTC0+PkZTTDogaW5jcmVtZW50IGkKZW5kCkZTTC0tPj5GU0xTOiByZXR1cm4gaQpsb29wIHdoaWxlIHNyY1tpXSAhPSAnXDAnIGFuZCBpIDwgKHNpemUgLSAxKQogICAgYWx0IGlmIHNpemUgPiAwCiAgICAgICAgRlNMUy0+PkZTTFM6IGNvcHkgc3JjW2ldIHRvIGRzdFtpXQogICAgICAgIEZTTFMtPj5GU0xTOiBpbmNyZW1lbnQgaQogICAgZWxzZQogICAgICAgIG5vdGUgb3ZlciBGU0xTOiBObyBvcGVyYXRpb24KICAgIGVuZAplbmQKRlNMUy0+PkZTTFM6IGFwcGVuZCAnXDAnIHRvIGRzdApGU0xTLS0+Pk06IHJldHVybiBmdF9zdHJsZW4oc3JjKQpNLT4+UEY6IGNhbGwgcHJpbnRmKCJbJXNdIGlzICVkLlxuIiwgZHN0LCBpKQpQRi0tPj5NOiBQcmludCB0aGUgcmVzdWx0 | G5: ft_strlcpy | H5: #include <stdio.h> size_t ft_strlen(const char *str) { size_t i; i = 0; while (str[i] != '\0') i++; return (i); } size_t ft_strlcpy(char *dst, const char *src, size_t size) { size_t i; i = 0; if (size > 0) { while (src[i] != '\0' && i < (size - 1)) { dst[i] = src[i]; i++; } dst[i] = '\0'; } return (ft_strlen(src)); } int main() { char *src = "1234567890"; char dst[50]; int i = ft_strlcpy(dst, src, 11); printf("[%s] is %d.\n", dst, i); }
A6: 1 | B6: 224 | C6: 1162 | D6: 1386 | E6: sequenceDiagram participant main as main() participant FSL as ft_strlen() participant FSLC as ft_strlcpy() participant PF as printf() main->>FSLC: Call ft_strlcpy(dst, src, 11) alt size > 0 note over FSLC: initialize i = 0 loop while src[i] != 0 and i < (size - 1) FSLC->>FSLC: dst[i] = src[i] FSLC->>FSLC: increment i end FSLC->>FSLC: dst[i] = '\0' FSLC->>FSL: call ft_strlen(src) FSL-->>FSLC: returns the length FSLC-->>main: return ft_strlen(src) else size <= 0 FSLC-->>main: return 0 end main->>PF: call printf("[%s] is %d.\n", dst, i) PF-->>main: print the result | F6: https://mermaid.ink/img/JSV7aW5pdDp7J3RoZW1lJzonZm9yZXN0J319JSUKc2VxdWVuY2VEaWFncmFtCnBhcnRpY2lwYW50IG1haW4gYXMgbWFpbigpCnBhcnRpY2lwYW50IEZTTCBhcyBmdF9zdHJsZW4oKQpwYXJ0aWNpcGFudCBGU0xDIGFzIGZ0X3N0cmxjcHkoKQpwYXJ0aWNpcGFudCBQRiBhcyBwcmludGYoKQptYWluLT4+RlNMQzogQ2FsbCBmdF9zdHJsY3B5KGRzdCwgc3JjLCAxMSkKYWx0IHNpemUgPiAwCiAgICBub3RlIG92ZXIgRlNMQzogaW5pdGlhbGl6ZSBpID0gMAogICAgbG9vcCB3aGlsZSBzcmNbaV0gIT0gMCBhbmQgaSA8IChzaXplIC0gMSkKICAgICAgICBGU0xDLT4+RlNMQzogZHN0W2ldID0gc3JjW2ldCiAgICAgICAgRlNMQy0+PkZTTEM6IGluY3JlbWVudCBpCiAgICBlbmQKICAgIEZTTEMtPj5GU0xDOiBkc3RbaV0gPSAnXDAnCiAgICBGU0xDLT4+RlNMOiBjYWxsIGZ0X3N0cmxlbihzcmMpCiAgICBGU0wtLT4+RlNMQzogcmV0dXJucyB0aGUgbGVuZ3RoCiAgICBGU0xDLS0+Pm1haW46IHJldHVybiBmdF9zdHJsZW4oc3JjKQplbHNlIHNpemUgPD0gMAogICAgRlNMQy0tPj5tYWluOiByZXR1cm4gMAplbmQKbWFpbi0+PlBGOiBjYWxsIHByaW50ZigiWyVzXSBpcyAlZC5cbiIsIGRzdCwgaSkKUEYtLT4+bWFpbjogcHJpbnQgdGhlIHJlc3VsdA== | G6: ft_strlcpy | H6: #include <stdio.h> size_t ft_strlen(const char *str) { size_t i; i = 0; while (str[i] != '\0') i++; return (i); } size_t ft_strlcpy(char *dst, const char *src, size_t size) { size_t i; i = 0; if (size > 0) { while (src[i] != '\0' && i < (size - 1)) { dst[i] = src[i]; i++; } dst[i] = '\0'; } return (ft_strlen(src)); } int main() { char *src = "1234567890"; char dst[50]; int i = ft_strlcpy(dst, src, 11); printf("[%s] is %d.\n", dst, i); }
